<?xml version="1.0" ?>
<!-- =================================================================================== -->
<!-- |    This document was autogenerated by xacro from mevi.xacro                     | -->
<!-- |    EDITING THIS FILE BY HAND IS NOT RECOMMENDED                                 | -->
<!-- =================================================================================== -->
<robot name="firefighter">
  <!-- THIS IS A BODY LINK -->
  <link name="body_link">
    <visual>
      <origin rpy="0 0 0" xyz="0 0 0"/>
      <geometry>
        <box size="1.54 0.75 1.4"/>
      </geometry>
      <material name="red">
            <color rgba="1 0 0 1"/>                
        </material>
    </visual>
  </link>

  <!-- THIS IS A WHEEL JOINT -->
  <joint name="frontwheel_lw_joint" type="continuous">
    <parent link="body_link"/>
    <child link="frontwheel_lw_link"/>
    <origin rpy="0 0 0 " xyz="-0.490 -0.375 -0.665"/>
    <axis xyz="0 1 0"/>
    <!-- axis y rotation-->
  </joint>

  <joint name="frontwheel_rw_joint" type="continuous">
    <parent link="body_link"/>
    <child link="frontwheel_rw_link"/>
    <origin rpy="0 0 0 " xyz="-0.490 0.375 -0.665"/>
    <axis xyz="0 1 0"/>
    <!-- axis y rotation-->
  </joint>
  
  <joint name="rearwheel_lw_joint" type="continuous">
    <parent link="body_link"/>
    <child link="rearwheel_lw_link"/>
    <origin rpy="0 0 0 " xyz="0.490 -0.375 -0.665"/>
    <axis xyz="0 1 0"/>
    <!-- axis y rotation-->
  </joint>

  <joint name="rearwheel_rw_joint" type="continuous">
    <parent link="body_link"/>
    <child link="rearwheel_rw_link"/>
    <origin rpy="0 0 0 " xyz="0.490 0.375 -0.665"/>
    <axis xyz="0 1 0"/>
    <!-- axis y rotation-->
  </joint>
  

  <!-- ####################### -->
  <!-- THIS IS A WHEEL LINK -->
  <link name="frontwheel_lw_link">
    <visual>
      <origin rpy="1.570795 0 0" xyz="0 0 0"/>
      <!-- rotation on x as degree on radians (1.570795 is 90 degree in euler)-->
      <geometry>
        <cylinder length="0.125" radius="0.185"/>
      </geometry>
      <material name="yellow">
              <color rgba="1 1 0 1"/>                
          </material>
    </visual>
  </link>

  <link name="frontwheel_rw_link">
    <visual>
      <origin rpy="1.570795 0 0" xyz="0 0 0"/>
      <!-- rotation on x as degree on radians (1.570795 is 90 degree in euler)-->
      <geometry>
        <cylinder length="0.125" radius="0.185"/>
      </geometry>
      <material name="yellow">
            <color rgba="1 1 0 1"/>                
        </material>
    </visual>
  </link>

  <link name="rearwheel_lw_link">
    <visual>
      <origin rpy="1.570795 0 0" xyz="0 0 0"/>
      <!-- rotation on x as degree on radians (1.570795 is 90 degree in euler)-->
      <geometry>
        <cylinder length="0.125" radius="0.185"/>
      </geometry>
      <material name="yellow">
            <color rgba="1 1 0 1"/>                
        </material>
    </visual>
  </link>

  <link name="rearwheel_rw_link">
    <visual>
      <origin rpy="1.570795 0 0" xyz="0 0 0"/>
      <!-- rotation on x as degree on radians (1.570795 is 90 degree in euler)-->
      <geometry>
        <cylinder length="0.125" radius="0.185"/>
      </geometry>
      <material name="yellow">
            <color rgba="1 1 0 1"/>                
        </material>
    </visual>
  </link>
  <!-- ####################### -->
</robot>
