<?xml version="1.0" ?>
<!-- =================================================================================== -->
<!-- |    This document was autogenerated by xacro from mevi_description.urdf.xacro    | -->
<!-- |    EDITING THIS FILE BY HAND IS NOT RECOMMENDED                                 | -->
<!-- =================================================================================== -->
<robot name="mevi">
  <!-- my name is Mevi-->
  <!-- variable -->
  <material name="chassis_mat">
    <color rgba="0.2 0.2 0.2 1"/>
    <!-- grey -->
  </material>
  <material name="tire_mat">
    <color rgba="1 1 1 1"/>
  </material>
  <gazebo reference="front_right_wheel">
    <mu1>0.95</mu1>
    <mu2>0.95</mu2>
    <minDepth>0.005</minDepth>
    <kp>1e8</kp>
    <material>Gazebo/Black</material>
  </gazebo>
  <gazebo reference="front_left_wheel">
    <mu1>0.95</mu1>
    <mu2>0.95</mu2>
    <minDepth>0.005</minDepth>
    <kp>1e8</kp>
    <material>Gazebo/Black</material>
  </gazebo>
  <gazebo reference="rear_right_wheel">
    <mu1>0.95</mu1>
    <mu2>0.95</mu2>
    <minDepth>0.005</minDepth>
    <kp>1e8</kp>
    <material>Gazebo/Black</material>
  </gazebo>
  <gazebo reference="rear_left_wheel">
    <mu1>0.95</mu1>
    <mu2>0.95</mu2>
    <minDepth>0.005</minDepth>
    <kp>1e8</kp>
    <material>Gazebo/Black</material>
  </gazebo>
  <!-- my name is Mevi-->
  <!-- variable -->
  <link name="fl_axle">
    <inertial>
      <mass value="1"/>
      <origin xyz="0 0 0"/>
      <inertia ixx="0.004" ixy="0.0" ixz="0.0" iyy="0.004" iyz="0.0" izz="0.004"/>
    </inertial>
  </link>
  <link name="fr_axle">
    <inertial>
      <mass value="1"/>
      <origin xyz="0 0 0"/>
      <inertia ixx="0.004" ixy="0.0" ixz="0.0" iyy="0.004" iyz="0.0" izz="0.004"/>
    </inertial>
  </link>
  <link name="front_right_wheel">
    <visual>
      <origin rpy="0 0 0" xyz="0 0 0"/>
      <geometry>
        <cylinder length="0.125" radius="0.185"/>
      </geometry>
      <material name="tire_mat"/>
    </visual>
    <collision>
      <origin rpy="0 0 0" xyz="0 0 0"/>
      <geometry>
        <cylinder length="0.125" radius="0.185"/>
      </geometry>
    </collision>
    <inertial>
      <origin rpy="0 0 0" xyz="0 0 0"/>
      <mass value="10.0"/>
      <inertia ixx="0.09858333333333331" ixy="0.0" ixz="0.0" iyy="0.09858333333333331" iyz="0.0" izz="0.171125"/>
    </inertial>
  </link>
  <link name="front_left_wheel">
    <visual>
      <origin rpy="0 0 0" xyz="0 0 0"/>
      <geometry>
        <cylinder length="0.125" radius="0.185"/>
      </geometry>
      <material name="tire_mat"/>
    </visual>
    <collision>
      <origin rpy="0 0 0" xyz="0 0 0"/>
      <geometry>
        <cylinder length="0.125" radius="0.185"/>
      </geometry>
    </collision>
    <inertial>
      <origin rpy="0 0 0" xyz="0 0 0"/>
      <mass value="10.0"/>
      <inertia ixx="0.09858333333333331" ixy="0.0" ixz="0.0" iyy="0.09858333333333331" iyz="0.0" izz="0.171125"/>
    </inertial>
  </link>
  <link name="rear_right_wheel">
    <visual>
      <origin rpy="0 0 0" xyz="0 0 0"/>
      <geometry>
        <cylinder length="0.125" radius="0.185"/>
      </geometry>
      <material name="tire_mat"/>
    </visual>
    <collision>
      <origin rpy="0 0 0" xyz="0 0 0"/>
      <geometry>
        <cylinder length="0.125" radius="0.185"/>
      </geometry>
    </collision>
    <inertial>
      <origin rpy="0 0 0" xyz="0 0 0"/>
      <mass value="10.0"/>
      <inertia ixx="0.09858333333333331" ixy="0.0" ixz="0.0" iyy="0.09858333333333331" iyz="0.0" izz="0.171125"/>
    </inertial>
  </link>
  <link name="rear_left_wheel">
    <visual>
      <origin rpy="0 0 0" xyz="0 0 0"/>
      <geometry>
        <cylinder length="0.125" radius="0.185"/>
      </geometry>
      <material name="tire_mat"/>
    </visual>
    <collision>
      <origin rpy="0 0 0" xyz="0 0 0"/>
      <geometry>
        <cylinder length="0.125" radius="0.185"/>
      </geometry>
    </collision>
    <inertial>
      <origin rpy="0 0 0" xyz="0 0 0"/>
      <mass value="10.0"/>
      <inertia ixx="0.09858333333333331" ixy="0.0" ixz="0.0" iyy="0.09858333333333331" iyz="0.0" izz="0.171125"/>
    </inertial>
  </link>
  <!-- my name is Mevi-->
  <!-- variable -->
  <link name="world">
    <visual>
      <origin rpy="0 0 0" xyz="0 0 0"/>
      <geometry>
        <box size="0.001 0.001 0.001"/>
      </geometry>
    </visual>
  </link>
  <joint name="world_to_vehicle_center" type="fixed">
    <parent link="world"/>
    <child link="chassis"/>
    <origin xyz="0.0 0.0 0.085"/>
    <axis xyz="0 0 1"/>
  </joint>
  <link name="chassis" type="fixed">
    <visual>
      <origin rpy="0 0 0" xyz="0 0 0"/>
      <geometry>
        <box size="1.49 0.83 0.03"/>
      </geometry>
      <material name="chassis_mat"/>
    </visual>
  </link>
  <joint name="front_right_steer_joint" type="revolute">
    <parent link="chassis"/>
    <child link="fr_axle"/>
    <origin rpy="1.57079633 0 0" xyz="-0.49 0.415 0"/>
    <axis xyz="0 1 0"/>
    <limit effort="500000" lower="-0.785398" upper="0.785398" velocity="250"/>
  </joint>
  <joint name="front_right_wheel_joint" type="continuous">
    <parent link="fr_axle"/>
    <child link="front_right_wheel"/>
    <origin rpy="0 0 0" xyz="0 0 0"/>
    <axis xyz="0 0 -1"/>
  </joint>
  <joint name="front_left_steer_joint" type="revolute">
    <parent link="chassis"/>
    <child link="fl_axle"/>
    <origin rpy="1.57079633 0 0" xyz="-0.49 -0.415 0"/>
    <axis xyz="0 1 0"/>
    <limit effort="500000" lower="-0.785398" upper="0.785398" velocity="250"/>
  </joint>
  <joint name="front_left_wheel_joint" type="continuous">
    <parent link="fl_axle"/>
    <child link="front_left_wheel"/>
    <origin rpy="0 0 0" xyz="0 0 0"/>
    <axis xyz="0 0 -1"/>
  </joint>
  <joint name="rear_right_wheel_joint" type="continuous">
    <parent link="chassis"/>
    <child link="rear_right_wheel"/>
    <origin rpy="1.57079633 0 0" xyz="0.49 0.415 0"/>
    <axis xyz="0 0 -1"/>
  </joint>
  <joint name="rear_left_wheel_joint" type="continuous">
    <parent link="chassis"/>
    <child link="rear_left_wheel"/>
    <origin rpy="1.57079633 0 0" xyz="0.49 -0.415 0"/>
    <axis xyz="0 0 -1"/>
  </joint>
  <gazebo>
    <plugin filename="libSdControlPlugin.so" name="sd_control">
      <chassis>base_link</chassis>
      <front_left_wheel>front_left_wheel_joint</front_left_wheel>
      <front_right_wheel>front_right_wheel_joint</front_right_wheel>
      <front_left_wheel_steering>front_left_steer_joint</front_left_wheel_steering>
      <front_right_wheel_steering>front_right_steer_joint</front_right_wheel_steering>
      <back_left_wheel>rear_left_wheel_joint</back_left_wheel>
      <back_right_wheel>rear_right_wheel_joint</back_right_wheel>
      <fl_wheel_steering_p_gain>1e4</fl_wheel_steering_p_gain>
      <fr_wheel_steering_p_gain>1e4</fr_wheel_steering_p_gain>
      <fl_wheel_steering_i_gain>0</fl_wheel_steering_i_gain>
      <fr_wheel_steering_i_gain>0</fr_wheel_steering_i_gain>
      <fl_wheel_steering_d_gain>3e2</fl_wheel_steering_d_gain>
      <fr_wheel_steering_d_gain>3e2</fr_wheel_steering_d_gain>
      <max_speed>22</max_speed>
      <max_torque>250</max_torque>
      <front_brake_torque>260</front_brake_torque>
      <back_brake_torque>260</back_brake_torque>
      <chassis_aero_force_gain>0.63045</chassis_aero_force_gain>
    </plugin>
  </gazebo>
  <gazebo>
    <plugin filename="libgazebo_ros_p3d.so" name="p3d">
      <bodyName>base_link</bodyName>
      <topicName>base_pose_ground_truth</topicName>
      <frameName>map</frameName>
      <updateRate>100.0</updateRate>
    </plugin>
  </gazebo>
  <gazebo>
    <plugin filename="libgazebo_ros_joint_state_publisher.so" name="joint_state_publisher">
      <robotNamespace>/mevi</robotNamespace>
      <jointName>front_left_wheel_joint, front_right_wheel_joint, front_left_steer_joint, front_right_steer_joint, rear_left_wheel_joint, rear_right_wheel_joint</jointName>
      <updateRate>100.0</updateRate>
      <alwaysOn>true</alwaysOn>
    </plugin>
  </gazebo>
</robot>
