<?xml version="1.0" ?>
<!-- =================================================================================== -->
<!-- |    This document was autogenerated by xacro from mevi.xacro                     | -->
<!-- |    EDITING THIS FILE BY HAND IS NOT RECOMMENDED                                 | -->
<!-- =================================================================================== -->
<robot name="firefighter">
  <!-- variable -->
  <gazebo reference="body_link">
    <mu1>0.2</mu1>
    <mu2>0.2</mu2>
    <material name="red">Gazebo/Red</material>
  </gazebo>
  <gazebo reference="frontwheel_lw_link">
    <mu1>0.2</mu1>
    <mu2>0.2</mu2>
    <material name="yellow">Gazebo/Yellow</material>
  </gazebo>
  <gazebo reference="frontwheel_rw_link">
    <mu1>0.2</mu1>
    <mu2>0.2</mu2>
    <material name="yellow">Gazebo/Yellow</material>
  </gazebo>
  <gazebo reference="rearwheel_lw_link">
    <mu1>0.2</mu1>
    <mu2>0.2</mu2>
    <material name="yellow">Gazebo/Yellow</material>
  </gazebo>
  <gazebo reference="rearwheel_rw_link">
    <mu1>0.2</mu1>
    <mu2>0.2</mu2>
    <material name="yellow">Gazebo/Yellow</material>
  </gazebo>
  <gazebo>
    <plugin filename="libgazebo_ros_skid_steer_drive.so" name="skid_steer_drive_controller">
      <updateRate>100</updateRate>
      <leftFrontJoint>frontwheel_lw_joint</leftFrontJoint>
      <rightFrontJoint>frontwheel_rw_joint</rightFrontJoint>
      <leftRearJoint>rearwheel_lw_joint</leftRearJoint>
      <rightRearJoint>rearwheel_rw_joint</rightRearJoint>
      <wheelSeparation>0.875</wheelSeparation>
      <wheelDiameter>0.37</wheelDiameter>
      <!--maximumTorque -->
      <torque>1000</torque>
      <commandTopic>cmd_vel</commandTopic>
      <odometryTopic>odom</odometryTopic>
      <odometryFrame>odom</odometryFrame>
      <robotBaseFrame>dummy</robotBaseFrame>
      <publishWheelTF>true</publishWheelTF>
      <publishOdom>true</publishOdom>
      <publishWheelJointState>true</publishWheelJointState>
      <covariance_x>0.0001</covariance_x>
      <covariance_y>0.0001</covariance_y>
      <covariance_yaw>0.01</covariance_yaw>
    </plugin>
  </gazebo>
  <!-- <gazebo>
        <plugin name="p3d_base_controller" filename="libgazebo_ros_p3d.so">
            <alwaysOn>true</alwaysOn>
            <updateRate>50.0</updateRate>
            <bodyName>body_link</bodyName>
            <topicName>ground_truth/state</topicName>
            <gaussianNoise>0.01</gaussianNoise>
            <frameName>world</frameName>
            <xyzOffsets>0 0 0</xyzOffsets>
            <rpyOffsets>0 0 0</rpyOffsets>
        </plugin>
    </gazebo> -->
  <!-- create a dummy joint and link in the simmulations -->
  <link name="dummy">
    <origin rpy="1.570795 0 0" xyz="0 0 0"/>
  </link>
  <joint name="dummy_joint" type="fixed">
    <parent link="dummy"/>
    <child link="body_link"/>
  </joint>
  <!-- THIS IS A BODY LINK -->
  <link name="body_link">
    <visual>
      <origin rpy="0 0 0" xyz="0 0 0"/>
      <geometry>
        <box size="1.54 0.75 1.4"/>
      </geometry>
      <!-- <material name="red">
            <color rgba="1 0 0 1"/>                
        </material> -->
    </visual>
    <collision>
      <origin rpy="0 0 0" xyz="0 0 0"/>
      <geometry>
        <box size="1.540 0.750 1.63"/>
      </geometry>
    </collision>
    <inertial>
      <origin rpy="0 0 0" xyz="0 0 0"/>
      <mass value="2182.95"/>
      <!-- moment inertia of body -->
      <!-- let we assume the wheel is a full cuboid, so
        ixx = Il = 1/12*m (w2 + h2)
        iyy = Iw = 1/12*m (l2 + h2)
        izz = Ih = 1/12*m (l2 + w2)
      -->
      <inertia ixx="458.8742812499999" ixy="0.0" ixz="0.0" iyy="787.9721849999999" iyz="0.0" izz="533.7494662499998"/>
    </inertial>
  </link>
  <!-- ####################### -->
  <!-- THIS IS A WHEEL JOINT -->
  <joint name="frontwheel_lw_joint" type="continuous">
    <parent link="body_link"/>
    <child link="frontwheel_lw_link"/>
    <origin rpy="0 0 0 " xyz="-0.490 -0.375 -0.665"/>
    <axis xyz="0 1 0"/>
    <!-- axis y rotation-->
    <limit effort="1000" velocity="1000"/>
    <dynamics damping="1.0" friction="1.0"/>
  </joint>
  <joint name="frontwheel_rw_joint" type="continuous">
    <parent link="body_link"/>
    <child link="frontwheel_rw_link"/>
    <origin rpy="0 0 0 " xyz="-0.490 0.375 -0.665"/>
    <axis xyz="0 1 0"/>
    <limit effort="1000" velocity="1000"/>
    <dynamics damping="1.0" friction="1.0"/>
    <!-- axis y rotation-->
  </joint>
  <joint name="rearwheel_lw_joint" type="continuous">
    <parent link="body_link"/>
    <child link="rearwheel_lw_link"/>
    <origin rpy="0 0 0 " xyz="0.490 -0.375 -0.665"/>
    <axis xyz="0 1 0"/>
    <!-- axis y rotation-->
    <limit effort="1000" velocity="1000"/>
    <dynamics damping="1.0" friction="1.0"/>
  </joint>
  <joint name="rearwheel_rw_joint" type="continuous">
    <parent link="body_link"/>
    <child link="rearwheel_rw_link"/>
    <origin rpy="0 0 0 " xyz="0.490 0.375 -0.665"/>
    <axis xyz="0 1 0"/>
    <!-- axis y rotation-->
    <limit effort="1000" velocity="1000"/>
    <dynamics damping="1.0" friction="1.0"/>
  </joint>
  <!-- ####################### -->
  <!-- THIS IS A WHEEL LINK -->
  <link name="frontwheel_lw_link">
    <visual>
      <origin rpy="1.570795 0 0" xyz="0 0 0"/>
      <!-- rotation on x as degree on radians (1.570795 is 90 degree in euler)-->
      <geometry>
        <cylinder length="0.125" radius="0.185"/>
      </geometry>
      <!-- <material name="yellow">
              <color rgba="1 1 0 1"/>                
          </material> -->
    </visual>
    <collision>
      <origin rpy="1.570795 0 0" xyz="0 0 0"/>
      <!-- rotation on x as degree on radians (1.570795 is 90 degree in euler)-->
      <geometry>
        <cylinder length="0.125" radius="0.185"/>
      </geometry>
      <!-- <material name="yellow">
            <color rgba="1 1 0 1"/>                
        </material> -->
    </collision>
    <inertial>
      <origin rpy="0 0 0" xyz="0 0 0"/>
      <mass value="14.784138661359375"/>
      <inertia ixx="0.14574696696990114" ixy="0.0" ixz="0.0" iyy="0.14574696696990114" iyz="0.0" izz="0.25299357284251234"/>
    </inertial>
  </link>
  <link name="frontwheel_rw_link">
    <visual>
      <origin rpy="1.570795 0 0" xyz="0 0 0"/>
      <!-- rotation on x as degree on radians (1.570795 is 90 degree in euler)-->
      <geometry>
        <cylinder length="0.125" radius="0.185"/>
      </geometry>
      <!-- <material name="yellow">
            <color rgba="1 1 0 1"/>                
        </material> -->
    </visual>
    <collision>
      <origin rpy="1.570795 0 0" xyz="0 0 0"/>
      <!-- rotation on x as degree on radians (1.570795 is 90 degree in euler)-->
      <geometry>
        <cylinder length="0.125" radius="0.185"/>
      </geometry>
      <!-- <material name="yellow">
          <color rgba="1 1 0 1"/>                
      </material> -->
    </collision>
    <inertial>
      <origin rpy="0 0 0" xyz="0 0 0"/>
      <mass value="14.784138661359375"/>
      <inertia ixx="0.14574696696990114" ixy="0.0" ixz="0.0" iyy="0.14574696696990114" iyz="0.0" izz="0.25299357284251234"/>
    </inertial>
  </link>
  <link name="rearwheel_lw_link">
    <visual>
      <origin rpy="1.570795 0 0" xyz="0 0 0"/>
      <!-- rotation on x as degree on radians (1.570795 is 90 degree in euler)-->
      <geometry>
        <cylinder length="0.125" radius="0.185"/>
      </geometry>
      <!-- <material name="yellow">
            <color rgba="1 1 0 1"/>                
        </material> -->
    </visual>
    <collision>
      <origin rpy="1.570795 0 0" xyz="0 0 0"/>
      <!-- rotation on x as degree on radians (1.570795 is 90 degree in euler)-->
      <geometry>
        <cylinder length="0.125" radius="0.185"/>
      </geometry>
      <!-- <material name="yellow">
          <color rgba="1 1 0 1"/>                
      </material> -->
    </collision>
    <inertial>
      <origin rpy="0 0 0" xyz="0 0 0"/>
      <mass value="14.784138661359375"/>
      <inertia ixx="0.14574696696990114" ixy="0.0" ixz="0.0" iyy="0.14574696696990114" iyz="0.0" izz="0.25299357284251234"/>
    </inertial>
  </link>
  <link name="rearwheel_rw_link">
    <visual>
      <origin rpy="1.570795 0 0" xyz="0 0 0"/>
      <!-- rotation on x as degree on radians (1.570795 is 90 degree in euler)-->
      <geometry>
        <cylinder length="0.125" radius="0.185"/>
      </geometry>
      <!-- <material name="yellow">
            <color rgba="1 1 0 1"/>                
        </material> -->
    </visual>
    <collision>
      <origin rpy="1.570795 0 0" xyz="0 0 0"/>
      <!-- rotation on x as degree on radians (1.570795 is 90 degree in euler)-->
      <geometry>
        <cylinder length="0.125" radius="0.185"/>
      </geometry>
      <!-- <material name="yellow">
          <color rgba="1 1 0 1"/>                
      </material> -->
    </collision>
    <inertial>
      <origin rpy="0 0 0" xyz="0 0 0"/>
      <mass value="14.784138661359375"/>
      <inertia ixx="0.14574696696990114" ixy="0.0" ixz="0.0" iyy="0.14574696696990114" iyz="0.0" izz="0.25299357284251234"/>
    </inertial>
  </link>
  <!-- ####################### -->
</robot>
